
[2018-01-17 17:51:10] Traceback (most recent call last):
  File "v8function_handler.pyx", line 42, in cefpython_py36.V8FunctionHandler_Execute (cefpython_py36.cpp:98999)
  File "gui.py", line 144, in savePath
    self._region.toGPX(fname)
  File "C:\Users\westphall\Spectrometer_Routefinder\RoutePlotter\ScanArea.py", line 584, in toGPX
    self._coords(),self._alt,self.boundBox)
TypeError: 'list' object is not callable


[2018-01-17 17:52:15] Traceback (most recent call last):
  File "v8function_handler.pyx", line 42, in cefpython_py36.V8FunctionHandler_Execute (cefpython_py36.cpp:98999)
  File "gui.py", line 144, in savePath
    self._region.toGPX(fname)
  File "C:\Users\westphall\Spectrometer_Routefinder\RoutePlotter\ScanArea.py", line 584, in toGPX
    self._coords,self._alt,self.boundBox)
  File "C:\Users\westphall\Spectrometer_Routefinder\RoutePlotter\GPXParse.py", line 160, in waypointsFromCoords
    .split('.')[0]+'Z' for i in range(len(coords))]
UnboundLocalError: local variable 'coords' referenced before assignment


[2018-01-17 17:54:07] Traceback (most recent call last):
  File "v8function_handler.pyx", line 42, in cefpython_py36.V8FunctionHandler_Execute (cefpython_py36.cpp:98999)
  File "gui.py", line 144, in savePath
    self._region.toGPX(fname)
  File "C:\Users\westphall\Spectrometer_Routefinder\RoutePlotter\ScanArea.py", line 584, in toGPX
    self._coords,self._alt,self.boundBox)
  File "C:\Users\westphall\Spectrometer_Routefinder\RoutePlotter\GPXParse.py", line 160, in waypointsFromCoords
    .split('.')[0]+'Z' for i in range(len(coords))]
UnboundLocalError: local variable 'coords' referenced before assignment


[2018-01-24 16:48:50] Traceback (most recent call last):
  File "v8function_handler.pyx", line 42, in cefpython_py36.V8FunctionHandler_Execute (cefpython_py36.cpp:96736)
TypeError: setSpectrometer() takes 2 positional arguments but 3 were given


[2018-01-24 17:29:53] Traceback (most recent call last):
  File "v8function_handler.pyx", line 42, in cefpython_py36.V8FunctionHandler_Execute (cefpython_py36.cpp:96736)
  File "gui.py", line 112, in setSpectrometer
    self._spectrometer = Spectrometer.spectrometerByName(val)()
  File "/home/mwestphall/MissionPlanner/AreaScanner/RoutePlotter/Spectrometer.py", line 89, in spectrometerByName
    }[name]
KeyError: 'Custom'


[2018-01-24 17:58:39] Traceback (most recent call last):
  File "gui.py", line 228, in <module>
    main()
  File "gui.py", line 209, in main
    external = External()
  File "gui.py", line 74, in __init__
    self.p = Process(target=TkSaveSubProc,args=(self.Q))
  File "/home/mwestphall/miniconda3/lib/python3.6/multiprocessing/process.py", line 80, in __init__
    self._args = tuple(args)
TypeError: 'Queue' object is not iterable


[2018-01-24 18:10:29] Traceback (most recent call last):
  File "gui.py", line 233, in <module>
    main()
  File "gui.py", line 222, in main
    external.p.join()
  File "/home/mwestphall/miniconda3/lib/python3.6/multiprocessing/process.py", line 123, in join
    assert self._popen is not None, 'can only join a started process'
AssertionError: can only join a started process


[2018-01-26 10:21:02] Traceback (most recent call last):
  File "gui.py", line 254, in <module>
    main()
  File "gui.py", line 241, in main
    TkSaveSubProc(FILE_QUEUE)
  File "gui.py", line 70, in TkSaveSubProc
    callback(fname)
  File "gui.py", line 161, in <lambda>
    callback = lambda f:self.finishLoad(f,js_callback)
  File "gui.py", line 165, in finishLoad
    region = ScanArea.ScanRegion.fromProjectShapeFile(fname,self._home)
  File "/home/mwestphall/MissionPlanner/AreaScanner/RoutePlotter/ScanArea.py", line 611, in fromProjectShapeFile
    meta = SHPParse.findMeta(shp_fname)
  File "/home/mwestphall/MissionPlanner/AreaScanner/RoutePlotter/SHPParse.py", line 34, in findMeta
    out = {key:[]for key in fields}
  File "/home/mwestphall/MissionPlanner/AreaScanner/RoutePlotter/SHPParse.py", line 34, in <dictcomp>
    out = {key:[]for key in fields}
TypeError: unhashable type: 'list'


[2018-01-26 10:21:44] Traceback (most recent call last):
  File "gui.py", line 254, in <module>
    main()
  File "gui.py", line 241, in main
    TkSaveSubProc(FILE_QUEUE)
  File "gui.py", line 70, in TkSaveSubProc
    callback(fname)
  File "gui.py", line 161, in <lambda>
    callback = lambda f:self.finishLoad(f,js_callback)
  File "gui.py", line 165, in finishLoad
    region = ScanArea.ScanRegion.fromProjectShapeFile(fname,self._home)
  File "/home/mwestphall/MissionPlanner/AreaScanner/RoutePlotter/ScanArea.py", line 611, in fromProjectShapeFile
    meta = SHPParse.findMeta(shp_fname)
  File "/home/mwestphall/MissionPlanner/AreaScanner/RoutePlotter/SHPParse.py", line 35, in findMeta
    out = {key:[]for key in fields}
  File "/home/mwestphall/MissionPlanner/AreaScanner/RoutePlotter/SHPParse.py", line 35, in <dictcomp>
    out = {key:[]for key in fields}
TypeError: unhashable type: 'list'


[2018-01-26 10:34:18] Traceback (most recent call last):
  File "gui.py", line 254, in <module>
    main()
  File "gui.py", line 241, in main
    TkSaveSubProc(FILE_QUEUE)
  File "gui.py", line 70, in TkSaveSubProc
    callback(fname)
  File "gui.py", line 161, in <lambda>
    callback = lambda f:self.finishLoad(f,js_callback)
  File "gui.py", line 165, in finishLoad
    region = ScanArea.ScanRegion.fromProjectShapeFile(fname,self._home)
  File "/home/mwestphall/MissionPlanner/AreaScanner/RoutePlotter/ScanArea.py", line 611, in fromProjectShapeFile
    meta = SHPParse.findMeta(shp_fname)
  File "/home/mwestphall/MissionPlanner/AreaScanner/RoutePlotter/SHPParse.py", line 34, in findMeta
    for record in records:
NameError: name 'records' is not defined


[2018-01-26 15:33:40] Traceback (most recent call last):
  File "gui.py", line 254, in <module>
    main()
  File "gui.py", line 241, in main
    TkSaveSubProc(FILE_QUEUE)
  File "gui.py", line 70, in TkSaveSubProc
    callback(fname)
  File "gui.py", line 161, in <lambda>
    callback = lambda f:self.finishLoad(f,js_callback)
  File "gui.py", line 165, in finishLoad
    region = ScanArea.ScanRegion.fromProjectShapeFile(fname,self._home)
  File "C:\Users\westphall\Spectrometer_Routefinder\RoutePlotter\ScanArea.py", line 610, in fromProjectShapeFile
    coords = SHPParse.findPolyCoords(shp_fname)
  File "C:\Users\westphall\Spectrometer_Routefinder\RoutePlotter\SHPParse.py", line 17, in findPolyCoords
    for shape in shpf.shapes():
  File "C:\Users\westphall\AppData\Local\Programs\Python\Python36\lib\site-packages\shapefile.py", line 435, in shapes
    shp = self.__getFileObj(self.shp)
  File "C:\Users\westphall\AppData\Local\Programs\Python\Python36\lib\site-packages\shapefile.py", line 301, in __getFileObj
    raise ShapefileException("Shapefile Reader requires a shapefile or file-like object.")
shapefile.ShapefileException: Shapefile Reader requires a shapefile or file-like object.


[2018-01-26 15:35:18] Traceback (most recent call last):
  File "gui.py", line 254, in <module>
    main()
  File "gui.py", line 241, in main
    TkSaveSubProc(FILE_QUEUE)
  File "gui.py", line 70, in TkSaveSubProc
    callback(fname)
  File "gui.py", line 161, in <lambda>
    callback = lambda f:self.finishLoad(f,js_callback)
  File "gui.py", line 165, in finishLoad
    region = ScanArea.ScanRegion.fromProjectShapeFile(fname,self._home)
  File "C:\Users\westphall\Spectrometer_Routefinder\RoutePlotter\ScanArea.py", line 610, in fromProjectShapeFile
    coords = SHPParse.findPolyCoords(shp_fname)
  File "C:\Users\westphall\Spectrometer_Routefinder\RoutePlotter\SHPParse.py", line 17, in findPolyCoords
    for shape in shpf.shapes():
  File "C:\Users\westphall\AppData\Local\Programs\Python\Python36\lib\site-packages\shapefile.py", line 435, in shapes
    shp = self.__getFileObj(self.shp)
  File "C:\Users\westphall\AppData\Local\Programs\Python\Python36\lib\site-packages\shapefile.py", line 301, in __getFileObj
    raise ShapefileException("Shapefile Reader requires a shapefile or file-like object.")
shapefile.ShapefileException: Shapefile Reader requires a shapefile or file-like object.


[2018-01-26 16:38:25] Traceback (most recent call last):
  File "v8function_handler.pyx", line 42, in cefpython_py36.V8FunctionHandler_Execute (cefpython_py36.cpp:98999)
  File "gui.py", line 168, in loadFile
    if not DIALOGS_ALLOWED:
UnboundLocalError: local variable 'DIALOGS_ALLOWED' referenced before assignment


[2018-01-26 16:39:45] Traceback (most recent call last):
  File "v8function_handler.pyx", line 42, in cefpython_py36.V8FunctionHandler_Execute (cefpython_py36.cpp:98999)
  File "gui.py", line 168, in loadFile
    if not DIALOGS_ALLOWED:
UnboundLocalError: local variable 'DIALOGS_ALLOWED' referenced before assignment


[2018-01-29 15:45:26] Traceback (most recent call last):
  File "gui.py", line 284, in <module>
    if __name__ == '__main__':
  File "gui.py", line 271, in main
    t.start()
  File "gui.py", line 31, in TkSaveThread
    args = tQ.get()
  File "C:\Users\westphall\AppData\Local\Programs\Python\Python36\lib\queue.py", line 164, in get
    self.not_empty.wait()
  File "C:\Users\westphall\AppData\Local\Programs\Python\Python36\lib\threading.py", line 295, in wait
    waiter.acquire()
KeyboardInterrupt


[2018-02-02 15:04:11] Traceback (most recent call last):
  File "v8function_handler.pyx", line 42, in cefpython_py36.V8FunctionHandler_Execute (cefpython_py36.cpp:98999)
  File "gui.py", line 216, in createPath
    region.findScanLines()
  File "C:\Users\westphall\Spectrometer_Routefinder\RoutePlotter\ScanArea.py", line 548, in findScanLines
    new_coords = sa.findScanLines()[1:]
  File "C:\Users\westphall\Spectrometer_Routefinder\RoutePlotter\ScanArea.py", line 342, in findScanLines
    parallel_dir1,self._perimeter[2],first_point)[::first_traverse]
  File "C:\Users\westphall\Spectrometer_Routefinder\RoutePlotter\ScanArea.py", line 270, in _findIntersectionsInDirection
    raise ScanLineDensityError
ScanArea.ScanLineDensityError

