
[2018-01-17 17:51:10] Traceback (most recent call last):
  File "v8function_handler.pyx", line 42, in cefpython_py36.V8FunctionHandler_Execute (cefpython_py36.cpp:98999)
  File "gui.py", line 144, in savePath
    self._region.toGPX(fname)
  File "C:\Users\westphall\Spectrometer_Routefinder\RoutePlotter\ScanArea.py", line 584, in toGPX
    self._coords(),self._alt,self.boundBox)
TypeError: 'list' object is not callable


[2018-01-17 17:52:15] Traceback (most recent call last):
  File "v8function_handler.pyx", line 42, in cefpython_py36.V8FunctionHandler_Execute (cefpython_py36.cpp:98999)
  File "gui.py", line 144, in savePath
    self._region.toGPX(fname)
  File "C:\Users\westphall\Spectrometer_Routefinder\RoutePlotter\ScanArea.py", line 584, in toGPX
    self._coords,self._alt,self.boundBox)
  File "C:\Users\westphall\Spectrometer_Routefinder\RoutePlotter\GPXParse.py", line 160, in waypointsFromCoords
    .split('.')[0]+'Z' for i in range(len(coords))]
UnboundLocalError: local variable 'coords' referenced before assignment


[2018-01-17 17:54:07] Traceback (most recent call last):
  File "v8function_handler.pyx", line 42, in cefpython_py36.V8FunctionHandler_Execute (cefpython_py36.cpp:98999)
  File "gui.py", line 144, in savePath
    self._region.toGPX(fname)
  File "C:\Users\westphall\Spectrometer_Routefinder\RoutePlotter\ScanArea.py", line 584, in toGPX
    self._coords,self._alt,self.boundBox)
  File "C:\Users\westphall\Spectrometer_Routefinder\RoutePlotter\GPXParse.py", line 160, in waypointsFromCoords
    .split('.')[0]+'Z' for i in range(len(coords))]
UnboundLocalError: local variable 'coords' referenced before assignment


[2018-01-24 16:48:50] Traceback (most recent call last):
  File "v8function_handler.pyx", line 42, in cefpython_py36.V8FunctionHandler_Execute (cefpython_py36.cpp:96736)
TypeError: setSpectrometer() takes 2 positional arguments but 3 were given


[2018-01-24 17:29:53] Traceback (most recent call last):
  File "v8function_handler.pyx", line 42, in cefpython_py36.V8FunctionHandler_Execute (cefpython_py36.cpp:96736)
  File "gui.py", line 112, in setSpectrometer
    self._spectrometer = Spectrometer.spectrometerByName(val)()
  File "/home/mwestphall/MissionPlanner/AreaScanner/RoutePlotter/Spectrometer.py", line 89, in spectrometerByName
    }[name]
KeyError: 'Custom'


[2018-01-24 17:58:39] Traceback (most recent call last):
  File "gui.py", line 228, in <module>
    main()
  File "gui.py", line 209, in main
    external = External()
  File "gui.py", line 74, in __init__
    self.p = Process(target=TkSaveSubProc,args=(self.Q))
  File "/home/mwestphall/miniconda3/lib/python3.6/multiprocessing/process.py", line 80, in __init__
    self._args = tuple(args)
TypeError: 'Queue' object is not iterable


[2018-01-24 18:10:29] Traceback (most recent call last):
  File "gui.py", line 233, in <module>
    main()
  File "gui.py", line 222, in main
    external.p.join()
  File "/home/mwestphall/miniconda3/lib/python3.6/multiprocessing/process.py", line 123, in join
    assert self._popen is not None, 'can only join a started process'
AssertionError: can only join a started process


[2018-01-26 10:21:02] Traceback (most recent call last):
  File "gui.py", line 254, in <module>
    main()
  File "gui.py", line 241, in main
    TkSaveSubProc(FILE_QUEUE)
  File "gui.py", line 70, in TkSaveSubProc
    callback(fname)
  File "gui.py", line 161, in <lambda>
    callback = lambda f:self.finishLoad(f,js_callback)
  File "gui.py", line 165, in finishLoad
    region = ScanArea.ScanRegion.fromProjectShapeFile(fname,self._home)
  File "/home/mwestphall/MissionPlanner/AreaScanner/RoutePlotter/ScanArea.py", line 611, in fromProjectShapeFile
    meta = SHPParse.findMeta(shp_fname)
  File "/home/mwestphall/MissionPlanner/AreaScanner/RoutePlotter/SHPParse.py", line 34, in findMeta
    out = {key:[]for key in fields}
  File "/home/mwestphall/MissionPlanner/AreaScanner/RoutePlotter/SHPParse.py", line 34, in <dictcomp>
    out = {key:[]for key in fields}
TypeError: unhashable type: 'list'


[2018-01-26 10:21:44] Traceback (most recent call last):
  File "gui.py", line 254, in <module>
    main()
  File "gui.py", line 241, in main
    TkSaveSubProc(FILE_QUEUE)
  File "gui.py", line 70, in TkSaveSubProc
    callback(fname)
  File "gui.py", line 161, in <lambda>
    callback = lambda f:self.finishLoad(f,js_callback)
  File "gui.py", line 165, in finishLoad
    region = ScanArea.ScanRegion.fromProjectShapeFile(fname,self._home)
  File "/home/mwestphall/MissionPlanner/AreaScanner/RoutePlotter/ScanArea.py", line 611, in fromProjectShapeFile
    meta = SHPParse.findMeta(shp_fname)
  File "/home/mwestphall/MissionPlanner/AreaScanner/RoutePlotter/SHPParse.py", line 35, in findMeta
    out = {key:[]for key in fields}
  File "/home/mwestphall/MissionPlanner/AreaScanner/RoutePlotter/SHPParse.py", line 35, in <dictcomp>
    out = {key:[]for key in fields}
TypeError: unhashable type: 'list'


[2018-01-26 10:34:18] Traceback (most recent call last):
  File "gui.py", line 254, in <module>
    main()
  File "gui.py", line 241, in main
    TkSaveSubProc(FILE_QUEUE)
  File "gui.py", line 70, in TkSaveSubProc
    callback(fname)
  File "gui.py", line 161, in <lambda>
    callback = lambda f:self.finishLoad(f,js_callback)
  File "gui.py", line 165, in finishLoad
    region = ScanArea.ScanRegion.fromProjectShapeFile(fname,self._home)
  File "/home/mwestphall/MissionPlanner/AreaScanner/RoutePlotter/ScanArea.py", line 611, in fromProjectShapeFile
    meta = SHPParse.findMeta(shp_fname)
  File "/home/mwestphall/MissionPlanner/AreaScanner/RoutePlotter/SHPParse.py", line 34, in findMeta
    for record in records:
NameError: name 'records' is not defined

